
析构函数不要抛出异常，如果析构函数内抛出异常应该直接处理，或者结束程序。

看这个例子:

```C++
#include<iostream>
#include<vector>
using namespace std;

class A {
private:
    vector<int> vec{1, 2, 3, 4, 5};
public:
    ~A() {
        for (int i : vec) {
            if (i > 3) {
                throw("exception");
            }
        }
    }
};


int main(int argc, char const *argv[])
{
    A a;
    return 0;
}
```

当 `~A()` 执行，大于 3 的时候会抛出一个异常，此时如果不捕获该异常，则程序就会崩溃掉。

如果vec 中是堆上的对象，则会发生内存泄漏。

因为有资源并未释放掉。

***析构函数出现异常的两种处理方式。***

第一种: 在析构函数内捕获异常，直接结束程序。

比如说：

```C++
#include<iostream>
#include<vector>
using namespace std;

class A {
private:
    vector<int> vec{1, 2, 3, 4, 5};
public:
    ~A() {
        for (int i : vec) {
            try {
                if (i > 3) {
                    throw("exception");
                }
            }
            catch ( ... ) {
                cout << "bug log" << endl;
                abort();
            }
        }
    }
};


int main(int argc, char const *argv[])
{
    A a;
    return 0;
}
```

第二种: 如果要对异常做出处理，应该提供一个单独的函数给客户(代指使用类A的人)调用。

```C++
#include<iostream>
#include<vector>
using namespace std;

class A {
private:
    int n;
    bool bClosed;
public:
    A(int n) : n(n) {
        bClosed = false;
    }
    ~A() {
        if(!bClosed) {
            try {
                close();
            }
            catch ( ... ) {
                cout << "bug log" << endl;
                // ...
            }
        }
    }

    void close() {
        // doSomething()
        if(!bClosed) {
            if (n > 3) {
                throw("exception");
            }
        }
        bClosed = true;
    }
};

class B {
private:
    A m_a;
public:
    B(const A &a) : m_a(a) {}
    ~B(){}
};



int main(int argc, char const *argv[])
{
    // 正常结束，A析构不会报错，1 < 3
    A a(1);
    B b(a);

    // 会抛异常，4 > 3
    A a(4);
    B b(a);
    return 0;
}
```

创建 a对象时，如果用小于 3 的数初始化，则执行类A的close则不会抛出异常。

如果用大于3的数初始化，则执行类A的close会抛出异常。

但是，注意，但是！！！

我们的类A提供了一个close函数给客户使用。

客户应该自己在结束的时候调用A的close函数，捕获可能的异常，做出相应的反应。

比如说像这样, 在 `~B()` 中

```C++
#include<iostream>
using namespace std;

class A {
private:
    int n;
    bool bClosed;
public:
    A(int n) : n(n) {
        bClosed = false;
    }
    ~A() {
        if(!bClosed) {
            try {
                close();
            }
            catch ( ... ) {
                cout << "bug log" << endl;
                // ...
            }
        }
    }

    void close() {
        // doSomething()
        if(!bClosed) {
            if (n > 3) {
                throw("exception");
            }
        }
        bClosed = true;
    }
};

class B {
private:
    A m_a;
public:
    B(const A &a) : m_a(a) {}
    ~B(){
        close();
    }
    void close() {
        try {
            m_a.close();
        }
        catch ( ... ) {
            cout << "B catch exception" << endl;
        }
    }
};



int main(int argc, char const *argv[])
{
    A a(4);
    B b(a);
    return 0;
}
```

由客户自己调用close并不会对他们带来负担，而是给他们一个处理错误的机会，否则他们没机会响应。

如果他们不认为这个机会有用（或许他们坚信不会有错误发生），可以忽略它。

则我们会在 `~A()` 中析构一次，此时如果发生错误，而且吞下异常。

客户没有立场抱怨，毕竟他们曾有机会第一手处理问题，而他们选择了放弃。




**公众号:** *cpp_yang*

**个人微信:** *yangxg_cxy*

**今日头条:** *程序员杨小哥*

**B站:** *https://space.bilibili.com/473029051*

**知乎:** *https://www.zhihu.com/people/cpp_yang*

  
  

















 